2021-01-29 16:36:12,120 ERROR: Exception on /unfollow/asa [POST] [in /usr/lib/python3/dist-packages/flask/app.py:1890]
Traceback (most recent call last):
  File "/usr/lib/python3/dist-packages/flask/app.py", line 2446, in wsgi_app
    response = self.full_dispatch_request()
  File "/usr/lib/python3/dist-packages/flask/app.py", line 1951, in full_dispatch_request
    rv = self.handle_user_exception(e)
  File "/usr/lib/python3/dist-packages/flask/app.py", line 1820, in handle_user_exception
    reraise(exc_type, exc_value, tb)
  File "/usr/lib/python3/dist-packages/flask/_compat.py", line 39, in reraise
    raise value
  File "/usr/lib/python3/dist-packages/flask/app.py", line 1949, in full_dispatch_request
    rv = self.dispatch_request()
  File "/usr/lib/python3/dist-packages/flask/app.py", line 1935, in dispatch_request
    return self.view_functions[rule.endpoint](**req.view_args)
  File "/home/selman/.local/lib/python3.8/site-packages/flask_login/utils.py", line 272, in decorated_view
    return func(*args, **kwargs)
  File "/home/selman/Desktop/microblog/app/main/routes.py", line 125, in unfollow
    flash('You are not following %(username)s.', username=username)
TypeError: flash() got an unexpected keyword argument 'username'
2021-01-29 16:37:39,181 ERROR: Exception on /follow/a [POST] [in /usr/lib/python3/dist-packages/flask/app.py:1890]
Traceback (most recent call last):
  File "/usr/lib/python3/dist-packages/flask/app.py", line 2446, in wsgi_app
    response = self.full_dispatch_request()
  File "/usr/lib/python3/dist-packages/flask/app.py", line 1951, in full_dispatch_request
    rv = self.handle_user_exception(e)
  File "/usr/lib/python3/dist-packages/flask/app.py", line 1820, in handle_user_exception
    reraise(exc_type, exc_value, tb)
  File "/usr/lib/python3/dist-packages/flask/_compat.py", line 39, in reraise
    raise value
  File "/usr/lib/python3/dist-packages/flask/app.py", line 1949, in full_dispatch_request
    rv = self.dispatch_request()
  File "/usr/lib/python3/dist-packages/flask/app.py", line 1935, in dispatch_request
    return self.view_functions[rule.endpoint](**req.view_args)
  File "/home/selman/.local/lib/python3.8/site-packages/flask_login/utils.py", line 272, in decorated_view
    return func(*args, **kwargs)
  File "/home/selman/Desktop/microblog/app/main/routes.py", line 106, in follow
    flash(_('You are following %(username)s!', username=username))
NameError: name '_' is not defined
2021-01-29 16:39:37,398 INFO: Microblog startup [in /home/selman/Desktop/microblog/app/__init__.py:68]
