2021-01-29 16:27:30,628 ERROR: Exception on /index [GET] [in /usr/lib/python3/dist-packages/flask/app.py:1890]
Traceback (most recent call last):
  File "/usr/lib/python3/dist-packages/flask/app.py", line 2446, in wsgi_app
    response = self.full_dispatch_request()
  File "/usr/lib/python3/dist-packages/flask/app.py", line 1951, in full_dispatch_request
    rv = self.handle_user_exception(e)
  File "/usr/lib/python3/dist-packages/flask/app.py", line 1820, in handle_user_exception
    reraise(exc_type, exc_value, tb)
  File "/usr/lib/python3/dist-packages/flask/_compat.py", line 39, in reraise
    raise value
  File "/usr/lib/python3/dist-packages/flask/app.py", line 1949, in full_dispatch_request
    rv = self.dispatch_request()
  File "/usr/lib/python3/dist-packages/flask/app.py", line 1935, in dispatch_request
    return self.view_functions[rule.endpoint](**req.view_args)
  File "/home/selman/.local/lib/python3.8/site-packages/flask_login/utils.py", line 272, in decorated_view
    return func(*args, **kwargs)
  File "/home/selman/Desktop/microblog/app/main/routes.py", line 44, in index
    return render_template('index.html', title='Home', form=form,
  File "/usr/lib/python3/dist-packages/flask/templating.py", line 137, in render_template
    return _render(
  File "/usr/lib/python3/dist-packages/flask/templating.py", line 120, in _render
    rv = template.render(context)
  File "/usr/lib/python3/dist-packages/jinja2/asyncsupport.py", line 76, in render
    return original_render(self, *args, **kwargs)
  File "/usr/lib/python3/dist-packages/jinja2/environment.py", line 1008, in render
    return self.environment.handle_exception(exc_info, True)
  File "/usr/lib/python3/dist-packages/jinja2/environment.py", line 780, in handle_exception
    reraise(exc_type, exc_value, tb)
  File "/usr/lib/python3/dist-packages/jinja2/_compat.py", line 37, in reraise
    raise value.with_traceback(tb)
  File "/home/selman/Desktop/microblog/app/templates/index.html", line 2, in <module>
    {% import 'bootstrap/wtf.html' as wtf %}
  File "/home/selman/Desktop/microblog/app/templates/base.html", line 1, in <module>
    {% extends 'bootstrap/base.html' %}
  File "/home/selman/.local/lib/python3.8/site-packages/flask_bootstrap/templates/bootstrap/base.html", line 1, in <module>
    {% block doc -%}
  File "/home/selman/.local/lib/python3.8/site-packages/flask_bootstrap/templates/bootstrap/base.html", line 4, in <module>
    {%- block html %}
  File "/home/selman/.local/lib/python3.8/site-packages/flask_bootstrap/templates/bootstrap/base.html", line 20, in <module>
    {% block body -%}
  File "/home/selman/.local/lib/python3.8/site-packages/flask_bootstrap/templates/bootstrap/base.html", line 23, in <module>
    {% block content -%}
  File "/home/selman/Desktop/microblog/app/templates/base.html", line 48, in <module>
    {% block app_content %}{% endblock %}
  File "/home/selman/Desktop/microblog/app/templates/index.html", line 11, in <module>
    {% include '_post.html' %}
  File "/home/selman/Desktop/microblog/app/templates/_post.html", line 11, in <module>
    <a href="{{ url_for('mainuser', username=post.author.username) }}">
  File "/usr/lib/python3/dist-packages/flask/helpers.py", line 370, in url_for
    return appctx.app.handle_url_build_error(error, endpoint, values)
  File "/usr/lib/python3/dist-packages/flask/app.py", line 2215, in handle_url_build_error
    reraise(exc_type, exc_value, tb)
  File "/usr/lib/python3/dist-packages/flask/_compat.py", line 39, in reraise
    raise value
  File "/usr/lib/python3/dist-packages/flask/helpers.py", line 357, in url_for
    rv = url_adapter.build(
  File "/usr/lib/python3/dist-packages/werkzeug/routing.py", line 2020, in build
    raise BuildError(endpoint, values, method, self)
werkzeug.routing.BuildError: Could not build url for endpoint 'mainuser' with values ['username']. Did you mean 'main.user' instead?
2021-01-29 16:30:01,514 INFO: Microblog startup [in /home/selman/Desktop/microblog/app/__init__.py:68]
2021-01-29 16:30:08,790 ERROR: Exception on /user/a [GET] [in /usr/lib/python3/dist-packages/flask/app.py:1890]
Traceback (most recent call last):
  File "/usr/lib/python3/dist-packages/flask/app.py", line 2446, in wsgi_app
    response = self.full_dispatch_request()
  File "/usr/lib/python3/dist-packages/flask/app.py", line 1951, in full_dispatch_request
    rv = self.handle_user_exception(e)
  File "/usr/lib/python3/dist-packages/flask/app.py", line 1820, in handle_user_exception
    reraise(exc_type, exc_value, tb)
  File "/usr/lib/python3/dist-packages/flask/_compat.py", line 39, in reraise
    raise value
  File "/usr/lib/python3/dist-packages/flask/app.py", line 1949, in full_dispatch_request
    rv = self.dispatch_request()
  File "/usr/lib/python3/dist-packages/flask/app.py", line 1935, in dispatch_request
    return self.view_functions[rule.endpoint](**req.view_args)
  File "/home/selman/.local/lib/python3.8/site-packages/flask_login/utils.py", line 272, in decorated_view
    return func(*args, **kwargs)
  File "/home/selman/Desktop/microblog/app/main/routes.py", line 73, in user
    return render_template('user.html', user=user, posts=posts.items,
  File "/usr/lib/python3/dist-packages/flask/templating.py", line 137, in render_template
    return _render(
  File "/usr/lib/python3/dist-packages/flask/templating.py", line 120, in _render
    rv = template.render(context)
  File "/usr/lib/python3/dist-packages/jinja2/asyncsupport.py", line 76, in render
    return original_render(self, *args, **kwargs)
  File "/usr/lib/python3/dist-packages/jinja2/environment.py", line 1008, in render
    return self.environment.handle_exception(exc_info, True)
  File "/usr/lib/python3/dist-packages/jinja2/environment.py", line 780, in handle_exception
    reraise(exc_type, exc_value, tb)
  File "/usr/lib/python3/dist-packages/jinja2/_compat.py", line 37, in reraise
    raise value.with_traceback(tb)
  File "/home/selman/Desktop/microblog/app/templates/user.html", line 1, in <module>
    {% extends "base.html" %}
  File "/home/selman/Desktop/microblog/app/templates/base.html", line 1, in <module>
    {% extends 'bootstrap/base.html' %}
  File "/home/selman/.local/lib/python3.8/site-packages/flask_bootstrap/templates/bootstrap/base.html", line 1, in <module>
    {% block doc -%}
  File "/home/selman/.local/lib/python3.8/site-packages/flask_bootstrap/templates/bootstrap/base.html", line 4, in <module>
    {%- block html %}
  File "/home/selman/.local/lib/python3.8/site-packages/flask_bootstrap/templates/bootstrap/base.html", line 20, in <module>
    {% block body -%}
  File "/home/selman/.local/lib/python3.8/site-packages/flask_bootstrap/templates/bootstrap/base.html", line 23, in <module>
    {% block content -%}
  File "/home/selman/Desktop/microblog/app/templates/base.html", line 48, in <module>
    {% block app_content %}{% endblock %}
  File "/home/selman/Desktop/microblog/app/templates/user.html", line 25, in <module>
    <form action="{{ url_for('main.unfollow', username=user.username) }}" method="post">
  File "/usr/lib/python3/dist-packages/flask/helpers.py", line 370, in url_for
    return appctx.app.handle_url_build_error(error, endpoint, values)
  File "/usr/lib/python3/dist-packages/flask/app.py", line 2215, in handle_url_build_error
    reraise(exc_type, exc_value, tb)
  File "/usr/lib/python3/dist-packages/flask/_compat.py", line 39, in reraise
    raise value
  File "/usr/lib/python3/dist-packages/flask/helpers.py", line 357, in url_for
    rv = url_adapter.build(
  File "/usr/lib/python3/dist-packages/werkzeug/routing.py", line 2020, in build
    raise BuildError(endpoint, values, method, self)
werkzeug.routing.BuildError: Could not build url for endpoint 'main.unfollow' with values ['username']. Did you mean 'main.follow' instead?
2021-01-29 16:34:11,155 INFO: Microblog startup [in /home/selman/Desktop/microblog/app/__init__.py:68]
2021-01-29 16:34:18,598 ERROR: Exception on /unfollow/a [POST] [in /usr/lib/python3/dist-packages/flask/app.py:1890]
Traceback (most recent call last):
  File "/usr/lib/python3/dist-packages/flask/app.py", line 2446, in wsgi_app
    response = self.full_dispatch_request()
  File "/usr/lib/python3/dist-packages/flask/app.py", line 1951, in full_dispatch_request
    rv = self.handle_user_exception(e)
  File "/usr/lib/python3/dist-packages/flask/app.py", line 1820, in handle_user_exception
    reraise(exc_type, exc_value, tb)
  File "/usr/lib/python3/dist-packages/flask/_compat.py", line 39, in reraise
    raise value
  File "/usr/lib/python3/dist-packages/flask/app.py", line 1949, in full_dispatch_request
    rv = self.dispatch_request()
  File "/usr/lib/python3/dist-packages/flask/app.py", line 1935, in dispatch_request
    return self.view_functions[rule.endpoint](**req.view_args)
  File "/home/selman/.local/lib/python3.8/site-packages/flask_login/utils.py", line 272, in decorated_view
    return func(*args, **kwargs)
  File "/home/selman/Desktop/microblog/app/main/routes.py", line 125, in unfollow
    flash('You are not following %(username)s.', username=username)
TypeError: flash() got an unexpected keyword argument 'username'
2021-01-29 16:35:18,893 INFO: Microblog startup [in /home/selman/Desktop/microblog/app/__init__.py:68]
